Workbook

Sheet Buku_Besar
A1: Kode Barang | B1: Nama Barang | C1: Jumlah Unit Stock Opname | D1: Unit Stock Opname | E1: Minimum Order / Unit | F1: Jumlah / Unit Serah Terima | G1: Satuan | H1: Harga Barang / Satuan (Rp) | I1: Harga Barang / Unit (Rp) | J1: Tanggal Masuk | K1: Tanggal Keluar | L1: Stock Awal | M1: Barang Masuk | N1: Barang Keluar | O1: Sisa Stock | P1: Nomor Dokumen | Q1: Nama Cabang/Unit Kerja | R1: PIC Cabang/Unit Kerja | S1: Tanggal Kirim | T1: Petugas Gudang | U1: Tanggal Barang diterima | V1: No FPKB | W1: No BAST | X1: Awal | Y1: Akhir | Z1: Keterangan | AA1: Status | AB1: Kode GL | AC1: Kategori GL | AD1: Keterangan GL | AE1: Sumber GL
A2: ATF-004 | B2: Kartu Flazz Persembahanku | C2: 403 | D2: Pcs | E2: 1 Pcs | F2: 1 | G2: Pcs | H2: 23000 | I2: 23000 | J2: 46185 | L2: 403 | O2: 403 | AB2: 1442305 | AC2: ATF | AD2: KARTU FLAZZ BCAS | AE2: Sudah ada (cocok sistem)
A3: ATF-004 | B3: Kartu Flazz Persembahanku | C3: 403 | D3: Pcs | E3: 1 Pcs | F3: 1 | G3: Pcs | H3: 23000 | I3: 23000 | J3: 46185 | M3: 1 | O3: 404 | Z3: Reject | AB3: 1442305 | AC3: ATF | AD3: KARTU FLAZZ BCAS | AE3: Sudah ada (cocok sistem)
A4: ATF-008 | B4: Flazz Edisi Haji | C4: 1 | D4: Pcs | E4: 1 Pcs | F4: 1 | G4: Pcs | H4: 23000 | I4: 23000 | J4: 46185 | L4: 1 | O4: 1 | Z4: Reject | AB4: 1442305 | AC4: ATF | AD4: KARTU FLAZZ BCAS | AE4: Sudah ada (cocok sistem)
A5: ATF-010 | B5: Flazz Edisi Masjid Pink | C5: 4 | D5: Pcs | E5: 1 Pcs | F5: 1 | G5: Pcs | H5: 23000 | I5: 23000 | J5: 46185 | L5: 4 | O5: 4 | Z5: Reject | AB5: 1442305 | AC5: ATF | AD5: KARTU FLAZZ BCAS | AE5: Sudah ada (cocok sistem)
A6: ATF-011 | B6: Flazz Edisi Tahajud | C6: 13 | D6: Pcs | E6: 1 Pcs | F6: 1 | G6: Pcs | H6: 23000 | I6: 23000 | J6: 46185 | L6: 13 | O6: 13 | Z6: Reject | AB6: 1442305 | AC6: ATF | AD6: KARTU FLAZZ BCAS | AE6: Sudah ada (cocok sistem)
A7: ATF-014 | B7: Flazz Green Earth | C7: 6 | D7: Pcs | E7: 1 Pcs | F7: 1 | G7: Pcs | H7: 35000 | I7: 35000 | J7: 46185 | L7: 6 | O7: 6 | AB7: 1442305 | AC7: ATF | AD7: KARTU FLAZZ BCAS | AE7: Sudah ada (cocok sistem)
A8: ATF-015 | B8: Flazz Logo BSya | C8: 3370 | D8: Pcs | E8: 1 Pcs | F8: 1 | G8: Pcs | H8: 35000 | I8: 35000 | J8: 46185 | L8: 3370 | O8: 3370 | AB8: 1442305 | AC8: ATF | AD8: KARTU FLAZZ BCAS | AE8: Sudah ada (cocok sistem)
A9: ATF-015 | B9: Flazz Logo BSya | C9: 3370 | D9: Pcs | E9: 1 Pcs | F9: 1 | G9: Pcs | H9: 35000 | I9: 35000 | K9: 46192 | N9: 1300 | O9: 2070 | P9: 104/FPP/LOG/2026 | Q9: KC Surabaya | S9: 46192 | T9: Ikbal | U9: 46195 | AB9: 1442305 | AC9: ATF | AD9: KARTU FLAZZ BCAS | AE9: Sudah ada (cocok sistem)
A10: ATF-015 | B10: Flazz Logo BSya | C10: 3370 | D10: Pcs | E10: 1 Pcs | F10: 1 | G10: Pcs | H10: 35000 | I10: 35000 | K10: 46209 | N10: 2 | O10: 2068 | P10: 00102/BAST-ASET/LOG/2026 | Q10: DJP | R10: Dinar | S10: 46209 | T10: Ikbal | U10: 46209 | AB10: 1442305 | AC10: ATF | AD10: KARTU FLAZZ BCAS | AE10: Sudah ada (cocok sistem)
A11: ATF-015 | B11: Flazz Logo BSya | C11: 3370 | D11: Pcs | E11: 1 Pcs | F11: 1 | G11: Pcs | H11: 35000 | I11: 35000 | K11: 46211 | N11: 1 | O11: 2067 | P11: 00104/BAST-ASET/LOG/2026 | Q11: MRK | R11: Kheni | S11: 46211 | T11: Ikbal | U11: 46211 | AB11: 1442305 | AC11: ATF | AD11: KARTU FLAZZ BCAS | AE11: Sudah ada (cocok sistem)
A12: ATF-016 | B12: Flazz BSya Kucing Naik Motor | C12: 10 | D12: Pcs | E12: 1 Pcs | F12: 1 | G12: Pcs | H12: 35000 | I12: 35000 | J12: 46185 | L12: 10 | O12: 10 | AB12: 1442305 | AC12: ATF | AD12: KARTU FLAZZ BCAS | AE12: Sudah ada (cocok sistem)
A13: ATMS-705 | B13: Laporan Kehilangan Kartu ATM | C13: 80 | D13: Pack | E13: 1 Pack | F13: 50 | G13: Set | H13: 475.2 | I13: 475.2 | J13: 46185 | L13: 80 | O13: 80 | AB13: 1442301 | AC13: CTK | AD13: BARANG CETAKAN | AE13: Sudah ada (cocok sistem)
A14: ATMS-705 | B14: Laporan Kehilangan Kartu ATM | C14: 80 | D14: Pack | E14: 1 Pack | F14: 50 | G14: Set | H14: 475.2 | I14: 475.2 | K14: 46192 | N14: 1 | O14: 79 | Q14: Cikini | R14: Hermanto | S14: 46192 | T14: Ikbal | U14: 46192 | W14: 095/BAST/ASET/LOG/2026 | AB14: 1442301 | AC14: CTK | AD14: BARANG CETAKAN | AE14: Sudah ada (cocok sistem)
A15: IDSS-001 | B15: Kartu Spesimen | C15: 1 | D15: Pack | E15: 1 Pack | F15: 100 | G15: Lembar | H15: 155.4 | I15: 155.4 | J15: 46185 | L15: 1 | O15: 1 | AB15: 1442301 | AC15: CTK | AD15: BARANG CETAKAN | AE15: Sudah ada (cocok sistem)
A16: IDSS-001 | B16: Kartu Spesimen | C16: 1 | D16: Pack | E16: 1 Pack | F16: 100 | G16: Lembar | H16: 155.4 | I16: 155.4 | K16: 46192 | N16: 1 | Q16: Cikini | R16: Hermanto | S16: 46192 | T16: Ikbal | U16: 46192 | W16: 095/BAST/ASET/LOG/2026 | AB16: 1442301 | AC16: CTK | AD16: BARANG CETAKAN | AE16: Sudah ada (cocok sistem)
A17: IDSS-001 | B17: Kartu Spesimen | C17: 1 | D17: Pack | E17: 1 Pack | F17: 100 | G17: Lembar | H17: 155.4 | I17: 155.4 | J17: 46212 | M17: 45 | P17: 076/SPS/LOG/2026 | AB17: 1442301 | AC17: CTK | AD17: BARANG CETAKAN | AE17: Sudah ada (cocok sistem)
A18: IDSS-002 | B18: Surat Kuasa | C18: 32 | D18: Pack | E18: 1 Pack | F18: 100 | G18: Lembar | H18: 222 | I18: 222 | J18: 46185 | L18: 32 | O18: 32 | AB18: 1442301 | AC18: CTK | AD18: BARANG CETAKAN | AE18: Sudah ada (cocok sistem)
A19: IDSS-002 | B19: Surat Kuasa | C19: 32 | D19: Pack | E19: 1 Pack | F19: 100 | G19: Lembar | H19: 222 | I19: 222 | K19: 46192 | N19: 1 | O19: 31 | Q19: Cikini | R19: Hermanto | S19: 46192 | T19: Ikbal | U19: 46192 | W19: 095/BAST/ASET/LOG/2026 | AB19: 1442301 | AC19: CTK | AD19: BARANG CETAKAN | AE19: Sudah ada (cocok sistem)
A20: IDSS-003 | B20: Overlay Tabungan | C20: 76 | D20: Pack | E20: 1 Pack | F20: 250 | G20: Lembar | J20: 46185 | L20: 76 | O20: 76 | AB20: 1442301 | AC20: CTK | AD20: BARANG CETAKAN | AE20: Sudah ada (cocok sistem)
A21: IDSS-003 | B21: Overlay Tabungan | C21: 76 | D21: Pack | E21: 1 Pack | F21: 250 | G21: Lembar | K21: 46188 | N21: 2 | O21: 74 | P21: 113/FPP/LOG/2026 | Q21: Ciledug | R21: Ferry Wijaya | S21: 46191 | T21: Ikbal | U21: 46191 | AB21: 1442301 | AC21: CTK | AD21: BARANG CETAKAN | AE21: Sudah ada (cocok sistem)
A22: IDSS-003 | B22: Overlay Tabungan | C22: 76 | D22: Pack | E22: 1 Pack | F22: 250 | G22: Lembar | K22: 46192 | N22: 4 | O22: 70 | P22: 136/FPP/LOG/2026 | Q22: Cikarang Selatan | R22: Harisa Utami | S22: 46192 | T22: Ikbal | U22: 46192 | AB22: 1442301 | AC22: CTK | AD22: BARANG CETAKAN | AE22: Sudah ada (cocok sistem)
A23: IDSS-003 | B23: Overlay Tabungan | C23: 76 | D23: Pack | E23: 1 Pack | F23: 250 | G23: Lembar | K23: 46192 | N23: 2 | O23: 68 | Q23: Cikini | R23: Hermanto | S23: 46192 | T23: Ikbal | U23: 46192 | W23: 095/BAST/ASET/LOG/2026 | AB23: 1442301 | AC23: CTK | AD23: BARANG CETAKAN | AE23: Sudah ada (cocok sistem)
A24: IDSS-003 | B24: Overlay Tabungan | C24: 76 | D24: Pack | E24: 1 Pack | F24: 250 | G24: Lembar | K24: 46180 | N24: 3 | O24: 65 | P24: 160/FPP/LOG/2026 | Q24: Palembang | R24: Ricki Aprianto | S24: 46209 | T24: Ikbal | U24: 46212 | V24: 00081/FPKB/LOG/2026 | W24: 114/BAST-ASET/LOG/2026 | AB24: 1442301 | AC24: CTK | AD24: BARANG CETAKAN | AE24: Sudah ada (cocok sistem)
A25: IDSS-003 | B25: Overlay Tabungan | C25: 76 | D25: Pack | E25: 1 Pack | F25: 250 | G25: Lembar | K25: 46191 | N25: 1 | O25: 64 | P25: 129/FPP/LOG/2026 | Q25: ULS Rivai Palembang | R25: Tri Adi Nanda | S25: 46191 | T25: Ikbal | U25: 46199 | AB25: 1442301 | AC25: CTK | AD25: BARANG CETAKAN | AE25: Sudah ada (cocok sistem)
A26: IDSS-004 | B26: Spectroline Tabungan | C26: 73 | D26: Pack | E26: 1 Pack | F26: 200 | G26: Lembar | J26: 46185 | L26: 73 | O26: 73 | AB26: 1442301 | AC26: CTK | AD26: BARANG CETAKAN | AE26: Sudah ada (cocok sistem)
A27: IDSS-004 | B27: Spectroline Tabungan | C27: 73 | D27: Pack | E27: 1 Pack | F27: 200 | G27: Lembar | K27: 46188 | N27: 10 | O27: 63 | P27: 113/FPP/LOG/2026 | Q27: Ciledug | R27: Ferry Wijaya | S27: 46191 | T27: Ikbal | U27: 46191 | AB27: 1442301 | AC27: CTK | AD27: BARANG CETAKAN | AE27: Sudah ada (cocok sistem)
A28: IDSS-004 | B28: Spectroline Tabungan | C28: 73 | D28: Pack | E28: 1 Pack | F28: 200 | G28: Lembar | K28: 46192 | N28: 3 | O28: 60 | P28: 136/FPP/LOG/2026 | Q28: Cikarang Selatan | R28: Harisa Utami | S28: 46192 | T28: Ikbal | U28: 46192 | AB28: 1442301 | AC28: CTK | AD28: BARANG CETAKAN | AE28: Sudah ada (cocok sistem)
A29: IDSS-004 | B29: Spectroline Tabungan | C29: 73 | D29: Pack | E29: 1 Pack | F29: 200 | G29: Lembar | K29: 46192 | N29: 2 | O29: 58 | Q29: Cikini | R29: Hermanto | S29: 46192 | T29: Ikbal | U29: 46192 | W29: 095/BAST/ASET/LOG/2026 | AB29: 1442301 | AC29: CTK | AD29: BARANG CETAKAN | AE29: Sudah ada (cocok sistem)
A30: IDSS-004 | B30: Spectroline Tabungan | C30: 73 | D30: Pack | E30: 1 Pack | F30: 200 | G30: Lembar | K30: 46192 | N30: 1 | O30: 57 | P30: 129/FPP/LOG/2026 | Q30: ULS Rivai Palembang | R30: Tri Adi Nanda | S30: 46191 | T30: Ikbal | U30: 46199 | AB30: 1442301 | AC30: CTK | AD30: BARANG CETAKAN | AE30: Sudah ada (cocok sistem)
A31: IDSS-004 | B31: Spectroline Tabungan | C31: 73 | D31: Pack | E31: 1 Pack | F31: 200 | G31: Lembar | K31: 46203 | N31: 6 | O31: 51 | P31: 161/FPP/LOG/2026 | Q31: KC Solo | R31: Nadia | S31: 46205 | T31: Ikbal | V31: 00082/FPKB/LOG/2026 | W31: 110/BAST-ASET/LOG/2026 | Z31: MCT2606008111425 | AA31: Pembebanan | AB31: 1442301 | AC31: CTK | AD31: BARANG CETAKAN | AE31: Sudah ada (cocok sistem)
A32: IDSS-004 | B32: Spectroline Tabungan | C32: 73 | D32: Pack | E32: 1 Pack | F32: 200 | G32: Lembar | K32: 46203 | N32: 5 | O32: 46 | P32: 160/FPP/LOG/2026 | Q32: Palembang | R32: Ricki Aprianto | S32: 46209 | T32: Ikbal | U32: 46212 | V32: 00081/FPKB/LOG/2026 | W32: 114/BAST-ASET/LOG/2026 | AB32: 1442301 | AC32: CTK | AD32: BARANG CETAKAN | AE32: Sudah ada (cocok sistem)
A33: IDSS-010 | B33: Nota Debet Syariah | C33: 4 | D33: Box | E33: 1 Box | F33: 1000 | G33: Lembar | H33: 482.85 | I33: 482850 | J33: 46185 | L33: 4 | O33: 4 | AB33: 1442301 | AC33: CTK | AD33: BARANG CETAKAN | AE33: Sudah ada (cocok sistem)
A34: IDSS-010 | B34: Nota Debet Syariah | C34: 4 | D34: Box | E34: 1 Box | F34: 1000 | G34: Lembar | H34: 482.85 | I34: 482850 | K34: 46192 | N34: 1 | O34: 3 | Q34: Cikini | R34: Hermanto | S34: 46192 | T34: Ikbal | U34: 46192 | W34: 095/BAST/ASET/LOG/2026 | AB34: 1442301 | AC34: CTK | AD34: BARANG CETAKAN | AE34: Sudah ada (cocok sistem)
A35: IDSS-010 | B35: Nota Debet Syariah | C35: 4 | D35: Box | E35: 1 Box | F35: 1000 | G35: Lembar | H35: 482.85 | I35: 482850 | K35: 46203 | N35: 1 | O35: 2 | P35: 161/FPP/LOG/2026 | Q35: KC Solo | R35: Nadia | S35: 46205 | T35: Ikbal | V35: 00082/FPKB/LOG/2026 | W35: 110/BAST-ASET/LOG/2026 | Z35: MCT2606008111425 | AA35: Pembebanan | AB35: 1442301 | AC35: CTK | AD35: BARANG CETAKAN | AE35: Sudah ada (cocok sistem)
A36: IDSS-103 | B36: Perubahan Deposito | C36: 30 | D36: Pack | E36: 1 Pack | F36: 100 | G36: Lembar | H36: 222 | I36: 222 | J36: 46185 | L36: 30 | O36: 30 | AB36: 1442301 | AC36: CTK | AD36: BARANG CETAKAN | AE36: Sudah ada (cocok sistem)
A37: IDSS-103 | B37: Perubahan Deposito | C37: 30 | D37: Pack | E37: 1 Pack | F37: 100 | G37: Lembar | H37: 222 | I37: 222 | K37: 46192 | N37: 1 | O37: 29 | Q37: Cikini | R37: Hermanto | S37: 46192 | T37: Ikbal | U37: 46192 | W37: 095/BAST/ASET/LOG/2026 | AB37: 1442301 | AC37: CTK | AD37: BARANG CETAKAN | AE37: Sudah ada (cocok sistem)
A38: IDSS-103 | B38: Perubahan Deposito | C38: 30 | D38: Pack | E38: 1 Pack | F38: 100 | G38: Lembar | H38: 222 | I38: 222 | K38: 46191 | N38: 1 | O38: 28 | P38: 108/FPP/LOG/2026 | Q38: KC Semarang | R38: Bernadhita | S38: 46191 | T38: Ikbal | U38: 46193 | V38: 00055/FPKB/LOG/2026 | W38: 100/BAST-ASET/LOG/2026 | AB38: 1442301 | AC38: CTK | AD38: BARANG CETAKAN | AE38: Sudah ada (cocok sistem)
A39: IDSS-104 | B39: Plastik Deposito | C39: 99 | D39: Pcs | E39: 1 Pcs | F39: 100 | G39: Lembar | H39: 1387.5 | I39: 1387.5 | J39: 46185 | L39: 99 | O39: 99 | AB39: 1442301 | AC39: CTK | AD39: BARANG CETAKAN | AE39: Sudah ada (cocok sistem)
A40: IDSS-104 | B40: Plastik Deposito | C40: 99 | D40: Pcs | E40: 1 Pcs | F40: 100 | G40: Lembar | H40: 1387.5 | I40: 1387.5 | K40: 46192 | N40: 1 | O40: 98 | Q40: Cikini | R40: Hermanto | S40: 46192 | T40: Ikbal | U40: 46192 | W40: 095/BAST/ASET/LOG/2026 | AB40: 1442301 | AC40: CTK | AD40: BARANG CETAKAN | AE40: Sudah ada (cocok sistem)
...

Sheet Harga_FIFO_Stok_Aktif
A1: Kategori | B1: GL | C1: Kode Barang | D1: Nama Barang | E1: Ada di Buku Besar | F1: Tingkat Harga ke- | G1: Jml Tingkat Aktif | H1: Qty Stock (satuan kecil) | I1: Harga Satuan (Rp) | J1: Nilai Stok (Rp)
A2: ATF | B2: 1442305 | C2: ATF-004 | D2: KARTU | E2: Ya | F2: 1 | G2: 1 | H2: 404 | I2: 23000 | J2: =H2*I2 -> 9292000
A3: ATF | B3: 1442305 | C3: ATF-008 | D3: KARTU | E3: Ya | F3: 1 | G3: 1 | H3: 1 | I3: 23000 | J3: =H3*I3 -> 23000
A4: ATF | B4: 1442305 | C4: ATF-010 | D4: KARTU | E4: Ya | F4: 1 | G4: 1 | H4: 4 | I4: 23000 | J4: =H4*I4 -> 92000
A5: ATF | B5: 1442305 | C5: ATF-011 | D5: KARTU | E5: Ya | F5: 1 | G5: 1 | H5: 13 | I5: 23000 | J5: =H5*I5 -> 299000
A6: ATF | B6: 1442305 | C6: ATF-014 | D6: FLAZZ | E6: Ya | F6: 1 | G6: 1 | H6: 6 | I6: 35000 | J6: =H6*I6 -> 210000
A7: ATF | B7: 1442305 | C7: ATF-015 | D7: FLAZZ | E7: Ya | F7: 1 | G7: 1 | H7: 3370 | I7: 35000 | J7: =H7*I7 -> 117950000
A8: ATF | B8: 1442305 | C8: ATF-016 | D8: FLAZZ | E8: Ya | F8: 1 | G8: 1 | H8: 10 | I8: 35000 | J8: =H8*I8 -> 350000
A9: CEK | B9: 1442105 | C9: IDSS-507 | D9: BUKU | E9: Ya | F9: 1 | G9: 1 | H9: 15000 | I9: 11093.35 | J9: =H9*I9 -> 166400250
A10: CEK | B10: 1442105 | C10: IDSS-508 | D10: BUKU | E10: Ya | F10: 1 | G10: 3 | H10: 10000 | I10: 3478.5 | J10: =H10*I10 -> 34785000
A11: CEK | B11: 1442105 | C11: IDSS-508 | D11: BUKU | E11: Ya | F11: 2 | G11: 3 | H11: 775 | I11: 10467.5 | J11: =H11*I11 -> 8112312.5
A12: CEK | B12: 1442105 | C12: IDSS-508 | D12: BUKU | E12: Ya | F12: 3 | G12: 3 | H12: 7500 | I12: 11043.4 | J12: =H12*I12 -> 82825500
A13: CTK | B13: 1442301 | C13: ATMS-705 | D13: LAPORAN | E13: Ya | F13: 1 | G13: 1 | H13: 4000 | I13: 475.2 | J13: =H13*I13 -> 1900800
... A134: TAB | B134: 1442102 | C134: IDSS-160 | D134: BUKU | E134: Ya | F134: 1 | G134: 1 | H134: 8890 | I134: 1887 | J134: =H134*I134 -> 16775430
I135: TOTAL | J135: =SUM(J2:J134) -> 9.8269157e+08

Sheet Ringkasan
A1: Ringkasan Nilai Stok Aktif per Kode GL (basis: snapshot sistem)
A3: Kategori | B3: Kode GL | C3: Keterangan | D3: Jml SKU ber-stok | E3: Nilai Stok (Rp)
A4: ATF | B4: 1442305 | C4: KARTU FLAZZ BCAS | D4: =SUMPRODUCT((Harga_FIFO_Stok_Aktif!$A$2:$A$134=A4)*(Harga_FIFO_Stok_Aktif!$F$2:$F$134=1)) -> 7 | E4: =SUMIFS(Harga_FIFO_Stok_Aktif!$J$2:$J$134,Harga_FIFO_Stok_Aktif!$A$2:$A$134,A4) -> 128216000
A5: ATK | B5: 1442302 | C5: ALAT TULIS KANTOR | D5: =SUMPRODUCT((Harga_FIFO_Stok_Aktif!$A$2:$A$134=A5)*(Harga_FIFO_Stok_Aktif!$F$2:$F$134=1)) -> 0 | E5: =SUMIFS(Harga_FIFO_Stok_Aktif!$J$2:$J$134,Harga_FIFO_Stok_Aktif!$A$2:$A$134,A5) -> 0
A6: CEK | B6: 1442105 | C6: BUKU CEK & BILYET GIRO | D6: =SUMPRODUCT((Harga_FIFO_Stok_Aktif!$A$2:$A$134=A6)*(Harga_FIFO_Stok_Aktif!$F$2:$F$134=1)) -> 2 | E6: =SUMIFS(Harga_FIFO_Stok_Aktif!$J$2:$J$134,Harga_FIFO_Stok_Aktif!$A$2:$A$134,A6) -> 2.9212306e+08
A7: CTK | B7: 1442301 | C7: BARANG CETAKAN | D7: =SUMPRODUCT((Harga_FIFO_Stok_Aktif!$A$2:$A$134=A7)*(Harga_FIFO_Stok_Aktif!$F$2:$F$134=1)) -> 74 | E7: =SUMIFS(Harga_FIFO_Stok_Aktif!$J$2:$J$134,Harga_FIFO_Stok_Aktif!$A$2:$A$134,A7) -> 2.1346556e+08
A8: DEP | B8: 1442103 | C8: BILYET DEPOSITO | D8: =SUMPRODUCT((Harga_FIFO_Stok_Aktif!$A$2:$A$134=A8)*(Harga_FIFO_Stok_Aktif!$F$2:$F$134=1)) -> 1 | E8: =SUMIFS(Harga_FIFO_Stok_Aktif!$J$2:$J$134,Harga_FIFO_Stok_Aktif!$A$2:$A$134,A8) -> 12175312
A9: LL2 | B9: 1442304 | C9: PERSEDIAAN BARANG LAINNYA | D9: =SUMPRODUCT((Harga_FIFO_Stok_Aktif!$A$2:$A$134=A9)*(Harga_FIFO_Stok_Aktif!$F$2:$F$134=1)) -> 6 | E9: =SUMIFS(Harga_FIFO_Stok_Aktif!$J$2:$J$134,Harga_FIFO_Stok_Aktif!$A$2:$A$134,A9) -> 30393250
A10: MTR | B10: 1442202 | C10: MATERAI - PERANGKO | D10: =SUMPRODUCT((Harga_FIFO_Stok_Aktif!$A$2:$A$134=A10)*(Harga_FIFO_Stok_Aktif!$F$2:$F$134=1)) -> 0 | E10: =SUMIFS(Harga_FIFO_Stok_Aktif!$J$2:$J$134,Harga_FIFO_Stok_Aktif!$A$2:$A$134,A10) -> 0
A11: PRO | B11: 1442303 | C11: BARANG PROMOSI | D11: =SUMPRODUCT((Harga_FIFO_Stok_Aktif!$A$2:$A$134=A11)*(Harga_FIFO_Stok_Aktif!$F$2:$F$134=1)) -> 24 | E11: =SUMIFS(Harga_FIFO_Stok_Aktif!$J$2:$J$134,Harga_FIFO_Stok_Aktif!$A$2:$A$134,A11) -> 239462527
A12: TAB | B12: 1442102 | C12: BUKU TABUNGAN | D12: =SUMPRODUCT((Harga_FIFO_Stok_Aktif!$A$2:$A$134=A12)*(Harga_FIFO_Stok_Aktif!$F$2:$F$134=1)) -> 4 | E12: =SUMIFS(Harga_FIFO_Stok_Aktif!$J$2:$J$134,Harga_FIFO_Stok_Aktif!$A$2:$A$134,A12) -> 66855855
C13: TOTAL | D13: =SUM(D4:D12) -> 118 | E13: =SUM(E4:E12) -> 9.8269157e+08
A15: CATATAN:
A16: 1. Sheet Buku_Besar = data manual kamu (349 baris, apa adanya) + 4 kolom baru: Kode GL (dilengkapi), Kategori GL, Keterangan GL, Sumber GL.
A17: 2. Sel KUNING = perlu konfirmasi manual: IDSS-302 & IDSS-505 (SKU tidak ada di sistem, GL diusulkan CTK/1442301) dan 1 sel tanggal IDSS-712 (' 4 ').
A18: 3. Sheet Harga_FIFO_Stok_Aktif = 133 baris harga dengan stok > 0 dari sistem (118 SKU). Baris BIRU = SKU dengan lebih dari 1 tingkat harga aktif (multi-batch FIFO).
A19: 4. Qty di sheet FIFO memakai SATUAN KECIL sistem (lembar/set/pcs), sedangkan stock opname Buku Besar memakai satuan besar (pack/box) - jangan dibandingkan langsung tanpa konversi.
A20: 5. Snapshot sistem berhenti di awal Juli 2026; mutasi setelahnya hanya ada di Buku Besar. 18 SKU ber-stok di sistem tidak muncul di Buku Besar (kolom 'Ada di Buku Besar' = Tidak) - kemungkinan belum dipindahkan.
A21: 6. Tiga tanggal tanpa tahun (9-Jul, 2-Jul, 14-Jul) dilengkapi menjadi 2026 sesuai konteks.
A22: Sumber: Buku_Besar.csv (manual, terupdate) + Persediaan_Gabungan_GL_Qty.xlsx (sistem lama, snapshot awal Juli 2026). Disusun 20 Jul 2026.
